Workbook

Sheet Database FG
A1: sku_code | B1: description | C1: pcs_cb | D1: kg_cb | E1: size | F1: country | G1: brand | H1: sub_brand | I1: category | J1: big_category | K1: house | L1: region | M1: speed | N1: pack_format | O1: line | P1: output
A2: 71576 | B2: NB RYL PREMATURE PRO+ 12X400G CN (MD) | C2: 12 | D2: =E2*C2/1000 -> 4.8 | E2: 400 | F2: Indonesia | G2: Nutrilon | H2: Nut Specialties | I2: Preterm | J2: TN | K2: Blue | L2: WEST | M2: 0 | N2: =VLOOKUP(A2, zcorin_converter!A:L, 12, FALSE) -> Canning | O2: 0 | P2: POWDER
A3: 91031 | B3: DUMEX HI-Q LACTOSE FREE 24X400G CN (TH) | C3: 24 | D3: =C3*E3/1000 -> 9.6 | E3: 400 | F3: Thailand | G3: Export | H3: Export | I3: Specialties | J3: TN | K3: Export | L3: WEST | M3: 0 | N3: =VLOOKUP(A3, zcorin_converter!A:L, 12, FALSE) -> Canning | O3: 0 | P3: POWDER
A4: 96011 | B4: NB RYL HA ALLERPRE 2 PRO+(12X400G CN) | C4: 12 | D4: =E4*C4/1000 -> 4.8 | E4: 400 | F4: Indonesia | G4: Nutrilon | H4: Nut Specialties | I4: HA | J4: TN | K4: Blue | L4: WEST | M4: 0 | N4: =VLOOKUP(A4, zcorin_converter!A:L, 12, FALSE) -> Canning | O4: 0 | P4: POWDER
A5: 97083 | B5: NUTRIBABY ROYAL ACTI DUOBIO 1 800GR | C5: 10 | D5: =E5*C5/1000 -> 8 | E5: 800 | F5: Indonesia | G5: Nutrilon | H5: Nutribaby 1 | I5: NR IF | J5: IF | K5: Blue | L5: WEST | M5: 0 | N5: =VLOOKUP(A5, zcorin_converter!A:L, 12, FALSE) -> Bag in Box | O5: 0 | P5: POWDER
A6: 97084 | B6: NUTRIBABY ROYAL ACTI DUOBIO 2 800GR | C6: 10 | D6: =E6*C6/1000 -> 8 | E6: 800 | F6: Indonesia | G6: Nutrilon | H6: Nutribaby 2 | I6: FO | J6: FO | K6: Blue | L6: WEST | M6: 0 | N6: =VLOOKUP(A6, zcorin_converter!A:L, 12, FALSE) -> Bag in Box | O6: 0 | P6: POWDER
A7: 97420 | B7: NUTRIBABY ROYAL ACTI DUOBIO 1 400GR | C7: 24 | D7: =E7*C7/1000 -> 9.6 | E7: 400 | F7: Indonesia | G7: Nutrilon | H7: Nutribaby 1 | I7: NR IF | J7: IF | K7: Blue | L7: WEST | M7: 0 | N7: =VLOOKUP(A7, zcorin_converter!A:L, 12, FALSE) -> Bag in Box | O7: 0 | P7: POWDER
A8: 97431 | B8: NUTRIBABY ROYAL ACTI DUOBIO 2 400GR | C8: 24 | D8: =E8*C8/1000 -> 9.6 | E8: 400 | F8: Indonesia | G8: Nutrilon | H8: Nutribaby 2 | I8: FO | J8: FO | K8: Blue | L8: EAST | M8: 0 | N8: =VLOOKUP(A8, zcorin_converter!A:L, 12, FALSE) -> Bag in Box | O8: 0 | P8: POWDER
A9: 99427 | B9: DUGRO SOY 24X200 G FB | C9: 24 | D9: =C9*E9/1000 -> 4.8 | E9: 200 | F9: Malaysia | G9: Export | H9: Export | I9: Soya GUM | J9: TN | K9: Export | L9: WEST | M9: 0 | N9: =VLOOKUP(A9, zcorin_converter!A:L, 12, FALSE) -> Bag in Box | O9: 0 | P9: POWDER
A10: 99428 | B10: DUGRO SOY 24X400 G FB | C10: 24 | D10: =C10*E10/1000 -> 9.6 | E10: 400 | F10: Malaysia | G10: Export | H10: Export | I10: Soya GUM | J10: TN | K10: Export | L10: WEST | M10: 0 | N10: =VLOOKUP(A10, zcorin_converter!A:L, 12, FALSE) -> Bag in Box | O10: 0 | P10: POWDER
A11: 99429 | B11: DUPRO SOY 24X400 G FB | C11: 24 | D11: =C11*E11/1000 -> 9.6 | E11: 400 | F11: Malaysia | G11: Export | H11: Export | I11: Soya IF | J11: TN | K11: Export | L11: WEST | M11: 0 | N11: =VLOOKUP(A11, zcorin_converter!A:L, 12, FALSE) -> Bag in Box | O11: 0 | P11: POWDER
A12: 99577 | B12: COW & GATE BLUE 24X400G CN (LK) | C12: 24 | D12: =C12*E12/1000 -> 9.6 | E12: 400 | F12: SriLanka | G12: Export | H12: Export | I12: FO | J12: FO | K12: Export | L12: WEST | M12: 0 | N12: =VLOOKUP(A12, zcorin_converter!A:L, 12, FALSE) -> Canning | O12: 0 | P12: POWDER
A13: 99578 | B13: COW & GATE FORMULA S N2 24X200G FB (LK) | C13: 24 | D13: =C13*E13/1000 -> 4.8 | E13: 200 | F13: SriLanka | G13: Export | H13: Export | I13: Soya FO | J13: TN | K13: Export | L13: WEST | M13: 0 | N13: =VLOOKUP(A13, zcorin_converter!A:L, 12, FALSE) -> Bag in Box | O13: 0 | P13: POWDER
A14: 99741 | B14: COW & GATE PREMIUM 1 24X200G FB (LK) | C14: 24 | D14: =C14*E14/1000 -> 4.8 | E14: 200 | F14: SriLanka | G14: Export | H14: Export | I14: IF | J14: IF | K14: Export | L14: WEST | M14: 0 | N14: =VLOOKUP(A14, zcorin_converter!A:L, 12, FALSE) -> Bag in Box | O14: 0 | P14: POWDER
A15: 99742 | B15: COW & GATE PREMIUM 1 24X400G CN (LK) | C15: 24 | D15: =C15*E15/1000 -> 9.6 | E15: 400 | F15: SriLanka | G15: Export | H15: Export | I15: IF | J15: IF | K15: Export | L15: WEST | M15: 0 | N15: =VLOOKUP(A15, zcorin_converter!A:L, 12, FALSE) -> Canning | O15: 0 | P15: POWDER
A16: 99747 | B16: COW & GATE BLUE 24X200G FB (LK) | C16: 24 | D16: =C16*E16/1000 -> 4.8 | E16: 200 | F16: SriLanka | G16: Export | H16: Export | I16: FO | J16: FO | K16: Export | L16: WEST | M16: 0 | N16: =VLOOKUP(A16, zcorin_converter!A:L, 12, FALSE) -> Bag in Box | O16: 0 | P16: POWDER
A17: 104713 | B17: KARICARE SOY 3X900G CN (AUS/NZ) ND | C17: 3 | D17: =C17*E17/1000 -> 2.7 | E17: 900 | F17: Australia | G17: Export | H17: Export | I17: Soya GUM | J17: TN | K17: Export | L17: WEST | M17: 0 | N17: =VLOOKUP(A17, zcorin_converter!A:L, 12, FALSE) -> Canning | O17: 0 | P17: POWDER
A18: 106546 | B18: MAMEX FL 24X400 G CN(MAL) ND | C18: 24 | D18: =C18*E18/1000 -> 9.6 | E18: 400 | F18: Malaysia | G18: Export | H18: Export | I18: Specialties | J18: TN | K18: Export | L18: WEST | M18: 0 | N18: =VLOOKUP(A18, zcorin_converter!A:L, 12, FALSE) -> Canning | O18: 0 | P18: POWDER
A19: 106550 | B19: APTAMIL FL 24X400 G CN (MM) | C19: 24 | D19: =C19*E19/1000 -> 9.6 | E19: 400 | F19: Malaysia | G19: Export | H19: Export | I19: Specialties | J19: TN | K19: Export | L19: WEST | M19: 0 | N19: =VLOOKUP(A19, zcorin_converter!A:L, 12, FALSE) -> Canning | O19: 0 | P19: POWDER
A20: 119419 | B20: SGM BBLR PRESI+ 24X400G FB LUM 2.0 | C20: 24 | D20: =C20*E20/1000 -> 9.6 | E20: 400 | F20: Malaysia | G20: Export | H20: Export | I20: Preterm | J20: TN | K20: Export | L20: WEST | M20: 0 | N20: =VLOOKUP(A20, zcorin_converter!A:L, 12, FALSE) -> Bag in Box | O20: 0 | P20: POWDER
A21: 126631 | B21: BEBELOVE 1 HiQEQ 24X400G FB RS | C21: 24 | D21: =E21*C21/1000 -> 9.6 | E21: 400 | F21: Indonesia | G21: Bebelac | H21: Bebelove 1 | I21: Bebelac IF | J21: IF | K21: Yellow | L21: WEST | M21: 0 | N21: =VLOOKUP(A21, zcorin_converter!A:L, 12, FALSE) -> Bag in Box | O21: 0 | P21: POWDER
A22: 126632 | B22: BEBELOVE 1 HiQEQ 12X800G CN RS | C22: 12 | D22: =E22*C22/1000 -> 9.6 | E22: 800 | F22: Indonesia | G22: Bebelac | H22: Bebelove 1 | I22: Bebelac IF | J22: IF | K22: Yellow | L22: WEST | M22: 0 | N22: =VLOOKUP(A22, zcorin_converter!A:L, 12, FALSE) -> Canning | O22: 0 | P22: POWDER
A23: 126633 | B23: BEBELOVE 1 HiQEQ 24X200G FB RS | C23: 24 | D23: =E23*C23/1000 -> 4.8 | E23: 200 | F23: Indonesia | G23: Bebelac | H23: Bebelove 1 | I23: Bebelac IF | J23: IF | K23: Yellow | L23: WEST | M23: 0 | N23: =VLOOKUP(A23, zcorin_converter!A:L, 12, FALSE) -> Bag in Box | O23: 0 | P23: POWDER
A24: 126634 | B24: BEBELOVE 1 HiQEQ 6X2X900G MP RS | C24: 6 | D24: =E24*C24/1000 -> 10.8 | E24: 1800 | F24: Indonesia | G24: Bebelac | H24: Bebelove 1 | I24: Bebelac IF | J24: IF | K24: Yellow | L24: WEST | M24: 0 | N24: =VLOOKUP(A24, zcorin_converter!A:L, 12, FALSE) -> Bag in Box | O24: 0 | P24: POWDER
A25: 126636 | B25: BEBELOVE 2 HiQEQ 24X200G FB RS | C25: 24 | D25: =E25*C25/1000 -> 4.8 | E25: 200 | F25: Indonesia | G25: Bebelac | H25: Bebelove 2 | I25: Bebelac FO | J25: FO | K25: Yellow | L25: WEST | M25: 0 | N25: =VLOOKUP(A25, zcorin_converter!A:L, 12, FALSE) -> Bag in Box | O25: 0 | P25: POWDER
A26: 126637 | B26: BEBELOVE 2 HiQEQ 24X400G FB RS | C26: 24 | D26: =E26*C26/1000 -> 9.6 | E26: 400 | F26: Indonesia | G26: Bebelac | H26: Bebelove 2 | I26: Bebelac FO | J26: FO | K26: Yellow | L26: WEST | M26: 0 | N26: =VLOOKUP(A26, zcorin_converter!A:L, 12, FALSE) -> Bag in Box | O26: 0 | P26: POWDER
A27: 126638 | B27: BEBELOVE 2 HiQEQ 12X800G CN RS | C27: 12 | D27: =E27*C27/1000 -> 9.6 | E27: 800 | F27: Indonesia | G27: Bebelac | H27: Bebelove 2 | I27: Bebelac FO | J27: FO | K27: Yellow | L27: WEST | M27: 0 | N27: =VLOOKUP(A27, zcorin_converter!A:L, 12, FALSE) -> Canning | O27: 0 | P27: POWDER
A28: 128113 | B28: DUMEX MAMIL GOLD SOY3 24X400 G CN (SG) | C28: 24 | D28: =C28*E28/1000 -> 9.6 | E28: 400 | F28: Singapore | G28: Export | H28: Export | I28: Soya GUM | J28: TN | K28: Export | L28: WEST | M28: 0 | N28: =VLOOKUP(A28, zcorin_converter!A:L, 12, FALSE) -> Canning | O28: 0 | P28: POWDER
A29: 128114 | B29: DUMEX MAMIL GOLD SOY3 12X800 G CN (SG) | C29: 12 | D29: =C29*E29/1000 -> 9.6 | E29: 800 | F29: Singapore | G29: Export | H29: Export | I29: Soya GUM | J29: TN | K29: Export | L29: WEST | M29: 0 | N29: =VLOOKUP(A29, zcorin_converter!A:L, 12, FALSE) -> Canning | O29: 0 | P29: POWDER
A30: 128115 | B30: DUMEX MAMIL GOLD SOY 1 3X900 G CN (SG) | C30: 3 | D30: =C30*E30/1000 -> 2.7 | E30: 900 | F30: Singapore | G30: Export | H30: Export | I30: Soya IF | J30: TN | K30: Export | L30: WEST | M30: 0 | N30: =VLOOKUP(A30, zcorin_converter!A:L, 12, FALSE) -> Canning | O30: 0 | P30: POWDER
A31: 129860 | B31: SGM LLM PRESINUTRI+ 24X400G FB GRD | C31: 24 | D31: =E31*C31/1000 -> 9.6 | E31: 400 | F31: Indonesia | G31: SGM | H31: LLM | I31: Low Lactose | J31: TN | K31: Red | L31: WEST | M31: 0 | N31: =VLOOKUP(A31, zcorin_converter!A:L, 12, FALSE) -> Bag in Box | O31: 0 | P31: POWDER
A32: 130061 | B32: SGM LLM PRESINUTRI+ 24X200G FB GRD | C32: 24 | D32: =E32*C32/1000 -> 4.8 | E32: 200 | F32: Indonesia | G32: SGM | H32: LLM | I32: Low Lactose | J32: TN | K32: Red | L32: WEST | M32: 0 | N32: =VLOOKUP(A32, zcorin_converter!A:L, 12, FALSE) -> Bag in Box | O32: 0 | P32: POWDER
A33: 130065 | B33: SGM SOYA ANANDA 6-12 24X400G FB GRD | C33: 24 | D33: =E33*C33/1000 -> 9.6 | E33: 400 | F33: Indonesia | G33: SGM | H33: SGM Soya 2 | I33: Soya FO | J33: TN | K33: Red | L33: WEST | M33: 0 | N33: =VLOOKUP(A33, zcorin_converter!A:L, 12, FALSE) -> Bag in Box | O33: 0 | P33: POWDER
A34: 130066 | B34: SGM SOYA ANANDA 6-12 10X700G FB GRD | C34: 10 | D34: =E34*C34/1000 -> 7 | E34: 700 | F34: Indonesia | G34: SGM | H34: SGM Soya 2 | I34: Soya FO | J34: TN | K34: Red | L34: WEST | M34: 0 | N34: =VLOOKUP(A34, zcorin_converter!A:L, 12, FALSE) -> Bag in Box | O34: 0 | P34: POWDER
A35: 130067 | B35: SGM SOYA ANANDA 0-6 24X200G FB GRD | C35: 24 | D35: =E35*C35/1000 -> 4.8 | E35: 200 | F35: Indonesia | G35: SGM | H35: SGM Soya 1 | I35: Soya IF | J35: TN | K35: Red | L35: WEST | M35: 0 | N35: =VLOOKUP(A35, zcorin_converter!A:L, 12, FALSE) -> Bag in Box | O35: 0 | P35: POWDER
A36: 130068 | B36: SGM SOYA EKSPLOR HNY 24X400G FB GRD | C36: 24 | D36: =E36*C36/1000 -> 9.6 | E36: 400 | F36: Indonesia | G36: SGM | H36: SGM Soya 3 | I36: Soya GUM | J36: TN | K36: Red | L36: WEST | M36: 0 | N36: =VLOOKUP(A36, zcorin_converter!A:L, 12, FALSE) -> Bag in Box | O36: 0 | P36: POWDER
A37: 130069 | B37: SGM SOYA EKSPLOR HNY 10X700G FB GRD | C37: 10 | D37: =E37*C37/1000 -> 7 | E37: 700 | F37: Indonesia | G37: SGM | H37: SGM Soya 3 | I37: Soya GUM | J37: TN | K37: Red | L37: WEST | M37: 0 | N37: =VLOOKUP(A37, zcorin_converter!A:L, 12, FALSE) -> Bag in Box | O37: 0 | P37: POWDER
A38: 130070 | B38: SGM SOYA EKSPLOR VAN 24X400G FB GRD | C38: 24 | D38: =E38*C38/1000 -> 9.6 | E38: 400 | F38: Indonesia | G38: SGM | H38: SGM Soya 3 | I38: Soya GUM | J38: TN | K38: Red | L38: WEST | M38: 0 | N38: =VLOOKUP(A38, zcorin_converter!A:L, 12, FALSE) -> Bag in Box | O38: 0 | P38: POWDER
A39: 130071 | B39: SGM SOYA EKSPLOR VAN 10X700G FB GRD | C39: 10 | D39: =E39*C39/1000 -> 7 | E39: 700 | F39: Indonesia | G39: SGM | H39: SGM Soya 3 | I39: Soya GUM | J39: TN | K39: Red | L39: WEST | M39: 0 | N39: =VLOOKUP(A39, zcorin_converter!A:L, 12, FALSE) -> Bag in Box | O39: 0 | P39: POWDER
A40: 130074 | B40: SGM BBLR PRESI+ 24X400G FB GRD | C40: 24 | D40: =E40*C40/1000 -> 9.6 | E40: 400 | F40: Indonesia | G40: SGM | H40: BBLR | I40: Preterm | J40: TN | K40: Red | L40: WEST | M40: 0 | N40: =VLOOKUP(A40, zcorin_converter!A:L, 12, FALSE) -> Bag in Box | O40: 0 | P40: POWDER
...

Sheet zcorin_converter
A1: material | B1: material_description | C1: country | D1: brand | E1: sub_brand | F1: category | G1: big_category | H1: house | I1: size | J1: pcs_cb | K1: kg_cb | L1: pack_format | M1: size_format | N1: insource_or_outsource | O1: machine_1 | P1: created_at | Q1: updated_at
A2: 1H1500 | B2: SGM E1+ HONEY 10X1500G FB BOLT | C2: Indonesia | D2: SGM | E2: SGM 3 | F2: SGM GUM | G2: GUM | I2: 1500.0 | J2: 10.0 | K2: 15.0 | L2: Bag in Box | M2: Big | N2: Insource | O2: GH | P2: 2026-01-14 07:35:15.367044+00 | Q2: 2026-01-14 07:35:15.367044+00
A3: 1H1050 | B3: SGM E1+ HONEY 10X1050G FB BOLT VAL PCK | C3: Indonesia | D3: SGM | E3: SGM 3 | F3: SGM GUM | G3: GUM | I3: 1050.0 | J3: 10.0 | K3: 10.5 | L3: Bag in Box | M3: Big | N3: Insource | O3: JK | P3: 2026-01-14 07:35:15.367044+00 | Q3: 2026-01-14 07:35:15.367044+00
A4: 3V1500 | B4: SGM E3+ VANILLA 10X1500G FB BOLT | C4: Indonesia | D4: SGM | E4: SGM 4 | F4: SGM GUM | G4: GUM | I4: 1500.0 | J4: 10.0 | K4: 15.0 | L4: Bag in Box | M4: Big | N4: Insource | O4: GH | P4: 2026-01-14 07:35:15.367044+00 | Q4: 2026-01-14 07:35:15.367044+00
A5: 3H1500 | B5: SGM E3+ HONEY 10X1500G FB BOLT | C5: Indonesia | D5: SGM | E5: SGM 4 | F5: SGM GUM | G5: GUM | I5: 1500.0 | J5: 10.0 | K5: 15.0 | L5: Bag in Box | M5: Big | N5: Insource | O5: GH | P5: 2026-01-14 07:35:15.367044+00 | Q5: 2026-01-14 07:35:15.367044+00
A6: 1V1500 | B6: SGM E1+ VANILLA 10X1500G FB BOLT | C6: Indonesia | D6: SGM | E6: SGM 3 | F6: SGM GUM | G6: GUM | I6: 1500.0 | J6: 10.0 | K6: 15.0 | L6: Bag in Box | M6: Big | N6: Insource | O6: GH | P6: 2026-01-14 07:35:15.367044+00 | Q6: 2026-01-14 07:35:15.367044+00
A7: 3V1050 | B7: SGM E3+ VANILLA 10X1050G FB BOLT VAL PCK | C7: Indonesia | D7: SGM | E7: SGM 4 | F7: SGM GUM | G7: GUM | I7: 1050.0 | J7: 10.0 | K7: 10.5 | L7: Bag in Box | M7: Big | N7: Insource | O7: JK | P7: 2026-01-14 07:35:15.367044+00 | Q7: 2026-01-14 07:35:15.367044+00
A8: 3H1050 | B8: SGM E3+ HONEY 10X1050G FB BOLT VAL PCK | C8: Indonesia | D8: SGM | E8: SGM 4 | F8: SGM GUM | G8: GUM | I8: 1050.0 | J8: 10.0 | K8: 10.5 | L8: Bag in Box | M8: Big | N8: Insource | O8: JK | P8: 2026-01-14 07:35:15.367044+00 | Q8: 2026-01-14 07:35:15.367044+00
A9: 1V1050 | B9: SGM E1+ VANILLA 10X1050G FB BOLT VAL PCK | C9: Indonesia | D9: SGM | E9: SGM 3 | F9: SGM GUM | G9: GUM | I9: 1050.0 | J9: 10.0 | K9: 10.5 | L9: Bag in Box | M9: Big | N9: Insource | O9: JK | P9: 2026-01-14 07:35:15.367044+00 | Q9: 2026-01-14 07:35:15.367044+00
A10: 196882A | B10: SGM E5+ CHOCO 10X900G FB GRD 2.1 BOLT | C10: Indonesia | D10: SGM | E10: SGM 5 | F10: SGM GUM | G10: GUM | I10: 900.0 | J10: 10.0 | K10: 9.0 | L10: Bag in Box | M10: Big | N10: Insource | O10: GH | P10: 2026-01-14 07:35:15.367044+00 | Q10: 2026-01-14 07:35:15.367044+00
A11: 196881A | B11: SGM E5+ HONEY 10X900G FB GRD 2.1 BOLT | C11: Indonesia | D11: SGM | E11: SGM 5 | F11: SGM GUM | G11: GUM | I11: 900.0 | J11: 10.0 | K11: 9.0 | L11: Bag in Box | M11: Big | N11: Insource | O11: GH | P11: 2026-01-14 07:35:15.367044+00 | Q11: 2026-01-14 07:35:15.367044+00
A12: 208362A | B12: SGM E5+ VANILLA 12X575G FB GRD 3.0 BOLT | C12: Indonesia | D12: SGM | E12: SGM 5 | F12: SGM GUM | G12: GUM | I12: 575.0 | J12: 12.0 | K12: 6.9 | L12: Bag in Box | M12: Big | N12: Insource | O12: JK | P12: 2026-01-14 07:35:15.367044+00 | Q12: 2026-01-14 07:35:15.367044+00
A13: 206030A | B13: SGM E5+ HONEY 12X575G FB ROBLOX BOLT | C13: Indonesia | D13: SGM | E13: SGM 5 | F13: SGM GUM | G13: GUM | I13: 575.0 | J13: 12.0 | K13: 6.9 | L13: Bag in Box | M13: Big | N13: Insource | O13: JK | P13: 2026-01-14 07:35:15.367044+00 | Q13: 2026-01-14 07:35:15.367044+00
... A39: 196642A | B39: SGM E1+ HONEY 48X150G FB GRD 2.1 BOLT | C39: Indonesia | D39: SGM | E39: SGM 3 | F39: SGM GUM | G39: GUM | I39: 150.0 | J39: 48.0 | K39: 7.2 | L39: Bag in Box | M39: Small | N39: Insource | O39: VW | P39: 2026-01-14 07:35:15.367044+00 | Q39: 2026-01-14 07:35:15.367044+00
A40: 196668A | B40: SGM ANANDA 6-12 10X1000G FB GRD 2.1 BOLT | C40: Indonesia | D40: SGM | E40: SGM 2 | F40: SGM FO | G40: FO | H40: Red | I40: 1000.0 | J40: 10.0 | K40: 10.0 | L40: Bag in Box | M40: Big | N40: Insource | O40: L2 | P40: 2026-01-14 07:35:15.367044+00 | Q40: 2026-01-14 07:35:15.367044+00
A41: 210728A | B41: SGM ANANDA 6-12 12X550G FB GRD FLASH BOLT | C41: Indonesia | D41: SGM | E41: SGM 2 | F41: SGM FO | G41: FO | H41: Red | I41: 550.0 | J41: 12.0 | K41: 6.6 | L41: Bag in Box | M41: Medium | N41: Insource | O41: L4 | P41: 2026-01-14 07:35:15.367044+00 | Q41: 2026-01-14 07:35:15.367044+00
A42: 196666A | B42: SGM ANANDA 6-12 24X400G FB GRD 2.1 BOLT | C42: Indonesia | D42: SGM | E42: SGM 2 | F42: SGM FO | G42: FO | H42: Red | I42: 400.0 | J42: 24.0 | K42: 9.6 | L42: Bag in Box | M42: Medium | N42: Insource | O42: L4 | P42: 2026-01-14 07:35:15.367044+00 | Q42: 2026-01-14 07:35:15.367044+00
A43: 196665A | B43: SGM ANANDA 6-12 48X150G FB GRD 2.1 BOLT | C43: Indonesia | D43: SGM | E43: SGM 2 | F43: SGM FO | G43: FO | H43: Red | I43: 150.0 | J43: 48.0 | K43: 7.2 | L43: Bag in Box | M43: Small | N43: Insource | O43: L3 | P43: 2026-01-14 07:35:15.367044+00 | Q43: 2026-01-14 07:35:15.367044+00
A44: 196664A | B44: SGM ANANDA 6-12 48X120G FB GRD 2.1 BOLT | C44: Indonesia | D44: SGM | E44: SGM 2 | F44: SGM FO | G44: FO | H44: Red | I44: 120.0 | J44: 48.0 | K44: 5.76 | L44: Bag in Box | M44: Small | N44: Insource | O44: L3 | P44: 2026-01-14 07:35:15.367044+00 | Q44: 2026-01-14 07:35:15.367044+00
A45: 196673A | B45: SGM ANANDA 0-6 10X1000G FB GRD 2.1 BOLT | C45: Indonesia | D45: SGM | E45: SGM 1 | F45: SGM IF | G45: IF | H45: Red | I45: 1000.0 | J45: 10.0 | K45: 10.0 | L45: Bag in Box | M45: Big | N45: Insource | O45: L2 | P45: 2026-01-14 07:35:15.367044+00 | Q45: 2026-01-14 07:35:15.367044+00
A46: 210729A | B46: SGM ANANDA 0-6 12X550G FB GRD FLASH BOLT | C46: Indonesia | D46: SGM | E46: SGM 1 | F46: SGM IF | G46: IF | H46: Red | I46: 550.0 | J46: 12.0 | K46: 6.6 | L46: Bag in Box | M46: Medium | N46: Insource | O46: L2 | P46: 2026-01-14 07:35:15.367044+00 | Q46: 2026-01-14 07:35:15.367044+00
A47: 196671A | B47: SGM ANANDA 0-6 24X400G FB GRD 2.1 BOLT | C47: Indonesia | D47: SGM | E47: SGM 1 | F47: SGM IF | G47: IF | H47: Red | I47: 400.0 | J47: 24.0 | K47: 9.6 | L47: Bag in Box | M47: Medium | N47: Insource | O47: L4 | P47: 2026-01-14 07:35:15.367044+00 | Q47: 2026-01-14 07:35:15.367044+00
A48: 196670A | B48: SGM ANANDA 0-6 48X150G FB GRD 2.1 BOLT | C48: Indonesia | D48: SGM | E48: SGM 1 | F48: SGM IF | G48: IF | H48: Red | I48: 150.0 | J48: 48.0 | K48: 7.2 | L48: Bag in Box | M48: Small | N48: Insource | O48: L3 | P48: 2026-01-14 07:35:15.367044+00 | Q48: 2026-01-14 07:35:15.367044+00
A49: 196669A | B49: SGM ANANDA 0-6 48X120G FB GRD 2.1 BOLT | C49: Indonesia | D49: SGM | E49: SGM 1 | F49: SGM IF | G49: IF | H49: Red | I49: 120.0 | J49: 48.0 | K49: 5.76 | L49: Bag in Box | M49: Small | N49: Insource | O49: L3 | P49: 2026-01-14 07:35:15.367044+00 | Q49: 2026-01-14 07:35:15.367044+00
A50: 213540 | B50: HIQ SG PLAIN 24X165ML SP RTD FC | C50: Thailand | D50: Export | E50: Export | F50: RTD | G50: RTD | H50: Export | I50: 165.0 | J50: 24.0 | K50: 4.1184 | L50: RTD | M50: Small | N50: Outsource | O50: 3rd Party | P50: 2026-01-14 07:35:15.367044+00 | Q50: 2026-01-14 07:35:15.367044+00
A51: 213541 | B51: DUMEX SG KID PLAIN 24X165 ML SP RTD FC | C51: Cambodia | D51: Export | E51: Export | F51: RTD | G51: RTD | H51: Export | I51: 165.0 | J51: 24.0 | K51: 4.1184 | L51: RTD | M51: Small | N51: Outsource | O51: 3rd Party | P51: 2026-01-14 07:35:15.367044+00 | Q51: 2026-01-14 07:35:15.367044+00
... A544: 143492 | B544: MILUPA LACTAMIL 21X200G FB BS | C544: Turkey | D544: Export | E544: Export | F544: P&BF | G544: P&BF | H544: Blue | I544: 200.0 | J544: 21.0 | K544: 4.2 | L544: Bag in Box | M544: Small | N544: Insource | O544: AB | P544: 2026-01-14 07:35:15.367044+00 | Q544: 2026-01-14 07:35:15.367044+00
A545: 140708 | B545: SGM AKTIF STRAW 10X4X110ML RTD MP | C545: Indonesia | D545: SGM | E545: SGM RTD | F545: SGM RTD | G545: RTD | H545: Red | K545: 4.597999226616531 | N545: Outsource | O545: 3rd Party | P545: 2026-01-14 07:35:15.367044+00 | Q545: 2026-01-14 07:35:15.367044+00
A546: 140705 | B546: SGM AKTIF CHOCO 10X4X110ML RTD MP | C546: Indonesia | D546: SGM | E546: SGM RTD | F546: SGM RTD | G546: RTD | H546: Red | K546: 4.5935996457416 | N546: Outsource | O546: 3rd Party | P546: 2026-01-14 07:35:15.367044+00 | Q546: 2026-01-14 07:35:15.367044+00
A547: 140702 | B547: LACTAMIL INISIS CHOCO 18X400G BS | C547: Indonesia | D547: Lactamil | E547: Lactamil | F547: Lactamil | G547: P&BF | H547: Blue | I547: 400.0 | J547: 18.0 | K547: 7.2 | L547: Bag in Box | M547: Medium | N547: Insource | O547: 3rd Party | P547: 2026-01-14 07:35:15.367044+00 | Q547: 2026-01-14 07:35:15.367044+00
A548: 140701 | B548: LACTAMIL LACT CHOCO 18X400G BS | C548: Indonesia | D548: Lactamil | E548: Lactamil | F548: Lactamil | G548: P&BF | H548: Blue | I548: 400.0 | J548: 18.0 | K548: 7.2 | L548: Bag in Box | M548: Medium | N548: Insource | O548: 3rd Party | P548: 2026-01-14 07:35:15.367044+00 | Q548: 2026-01-14 07:35:15.367044+00
A549: 140440 | B549: LACTAMIL PREG VANILA 18X400G BS | C549: Indonesia | D549: Lactamil | E549: Lactamil | F549: Lactamil | G549: P&BF | H549: Blue | I549: 400.0 | J549: 18.0 | K549: 7.2 | L549: Bag in Box | M549: Medium | N549: Insource | O549: AB | P549: 2026-01-14 07:35:15.367044+00 | Q549: 2026-01-14 07:35:15.367044+00
A550: 140439 | B550: LACTAMIL PREG CHOCO 18X400G BS | C550: Indonesia | D550: Lactamil | E550: Lactamil | F550: Lactamil | G550: P&BF | H550: Blue | I550: 400.0 | J550: 18.0 | K550: 7.2 | L550: Bag in Box | M550: Medium | N550: Insource | O550: 3rd Party | P550: 2026-01-14 07:35:15.367044+00 | Q550: 2026-01-14 07:35:15.367044+00
A551: 140438 | B551: LACTAMIL LACT VAN 18X400G BS | C551: Indonesia | D551: Lactamil | E551: Lactamil | F551: Lactamil | G551: P&BF | H551: Blue | I551: 400.0 | J551: 18.0 | K551: 7.2 | L551: Bag in Box | M551: Medium | N551: Insource | O551: AB | P551: 2026-01-14 07:35:15.367044+00 | Q551: 2026-01-14 07:35:15.367044+00
A552: 140437 | B552: LACTAMIL LACT CHOCO 21X200G BS | C552: Indonesia | D552: Lactamil | E552: Lactamil | F552: Lactamil | G552: P&BF | H552: Blue | I552: 200.0 | J552: 21.0 | K552: 4.2 | L552: Bag in Box | M552: Small | N552: Insource | O552: 3rd Party | P552: 2026-01-14 07:35:15.367044+00 | Q552: 2026-01-14 07:35:15.367044+00
A553: 140436 | B553: LACTAMIL PREG VANILA 21X200G BS | C553: Indonesia | D553: Lactamil | E553: Lactamil | F553: Lactamil | G553: P&BF | H553: Blue | I553: 200.0 | J553: 21.0 | K553: 4.2 | L553: Bag in Box | M553: Small | N553: Insource | O553: AB | P553: 2026-01-14 07:35:15.367044+00 | Q553: 2026-01-14 07:35:15.367044+00
A554: 140435 | B554: LACTAMIL PREG CHOCO 21X200G BS | C554: Indonesia | D554: Lactamil | E554: Lactamil | F554: Lactamil | G554: P&BF | H554: Blue | I554: 200.0 | J554: 21.0 | K554: 4.2 | L554: Bag in Box | M554: Small | N554: Insource | O554: 3rd Party | P554: 2026-01-14 07:35:15.367044+00 | Q554: 2026-01-14 07:35:15.367044+00
A555: 140434 | B555: LACTAMIL PREG STRAW 21X200G BS | C555: Indonesia | D555: Lactamil | E555: Lactamil | F555: Lactamil | G555: P&BF | H555: Blue | I555: 200.0 | J555: 21.0 | K555: 4.2 | L555: Bag in Box | M555: Small | N555: Insource | O555: AB | P555: 2026-01-14 07:35:15.367044+00 | Q555: 2026-01-14 07:35:15.367044+00
A556: 140433 | B556: LACTAMIL INISIS CHOCO 21X200G BS | C556: Indonesia | D556: Lactamil | E556: Lactamil | F556: Lactamil | G556: P&BF | H556: Blue | I556: 200.0 | J556: 21.0 | K556: 4.2 | L556: Bag in Box | M556: Small | N556: Insource | O556: 3rd Party | P556: 2026-01-14 07:35:15.367044+00 | Q556: 2026-01-14 07:35:15.367044+00
A557: 140328 | B557: BEBELAC 5 HNY HiQEQ 10X700G FB PDW | C557: Indonesia | D557: Bebelac | E557: Bebelac 5 | F557: Bebelac GUM | G557: GUM | H557: Yellow | I557: 700.0 | J557: 10.0 | K557: 7.0 | L557: Bag in Box | M557: Big | N557: Insource | O557: ROV1 | P557: 2026-01-14 07:35:15.367044+00 | Q557: 2026-01-14 07:35:15.367044+00
...

Sheet master_dps_east
A1: material | B1: description | C1: size | D1: pcs_cb | E1: kg_cb | F1: line | G1: speed
A2: 163659 | B2: BEBELAC 3 VAN HIQEQ 24X400G FB RS NMD | C2: 400 | D2: 24 | E2: 9.6 | F2: XY | G2: 112.5
A3: 163853 | B3: BEBELAC 3 VAN HIQEQ 10X1000G FB RS NMD | C3: 1000 | D3: 10 | E3: 10 | F3: XY | G3: 175
A4: 164030 | B4: BEBELAC 3 HNY HIQEQ 24X200G FB RS NMD | C4: 200 | D4: 24 | E4: 4.8 | F4: XY | G4: 83.333333
A5: 163660 | B5: BEBELAC 3 HNY HIQEQ 24X400G FB RS NMD | C5: 400 | D5: 24 | E5: 9.6 | F5: XY | G5: 112.5
A6: 163854 | B6: BEBELAC 3 HNY HIQEQ 10X1000G FB RS NMD | C6: 1000 | D6: 10 | E6: 10 | F6: XY | G6: 166.66667
A7: 126550 | B7: BEBELAC 4 VAN HiQEQ 24X400G FB RS | C7: 400 | D7: 24 | E7: 9.6 | F7: XY | G7: 112.5
A8: 130267 | B8: BEBELAC 4 VAN HiQEQ 10X1000G FB RS | C8: 1000 | D8: 10 | E8: 10 | F8: XY | G8: 166.66667
A9: 126549 | B9: BEBELAC 4 HNY HiQEQ 24X400G FB RS | C9: 400 | D9: 24 | E9: 9.6 | F9: XY | G9: 112.5
A10: 127644 | B10: BEBELAC 4 HNY HiQEQ 10X1000G FB RS | C10: 1000 | D10: 10 | E10: 10 | F10: XY | G10: 166.66667
A11: 158324 | B11: SGM ANANDA 6-12 48X120G FB GRD 2.0 | C11: 120 | D11: 48 | E11: 5.76 | F11: XY | G11: 0
A12: 158325 | B12: SGM ANANDA 6-12 48X150G FB GRD 2.0 | C12: 150 | D12: 48 | E12: 7.2 | F12: XY | G12: 100
A13: 158066 | B13: SGM ANANDA 6-12 21X400G FB GRD 2.0 | C13: 400 | D13: 21 | E13: 8.4 | F13: XY | G13: 175
... A40: 178506 | B40: BEBELAC 3 VAN GREAT+ 10X1000G FB PGS | C40: 1000 | D40: 10 | E40: 10 | F40: XY | G40: 166.66667
A41: 178496 | B41: BEBELAC 3 VAN GREAT+ 6X2X900G MP PGS | C41: 1800 | D41: 6 | E41: 10.8 | F41: XY | G41: NaN
A42: 178515 | B42: BEBELAC 3 HNY GREAT+ 24X200G FB PGS | C42: 200 | D42: 24 | E42: 4.8 | F42: XY | G42: 83.333333
A43: 178480 | B43: BEBELAC 3 HNY GREAT+ 24X400G FB PGS | C43: 400 | D43: 24 | E43: 9.6 | F43: XY | G43: 112.5
A44: 178507 | B44: BEBELAC 3 HNY GREAT+ 10X1000G FB PGS | C44: 1000 | D44: 10 | E44: 10 | F44: XY | G44: 166.66667
A45: 178497 | B45: BEBELAC 3 HNY GREAT+ 6X2X900G MP PGS | C45: 1800 | D45: 6 | E45: 10.8 | F45: XY | G45: NaN
A46: 178481 | B46: BEBELAC 4 VAN GREAT+ 24X400G FB PGS | C46: 400 | D46: 24 | E46: 9.6 | F46: XY | G46: 112.5
A47: 178508 | B47: BEBELAC 4 VAN GREAT+ 10X1000G FB PGS | C47: 1000 | D47: 10 | E47: 10 | F47: XY | G47: 166.66667
A48: 178498 | B48: BEBELAC 4 VAN GREAT+ 6X2X900G MP PGS | C48: 1800 | D48: 6 | E48: 10.8 | F48: XY | G48: NaN
A49: 178482 | B49: BEBELAC 4 HNY GREAT+ 24X400G FB PGS | C49: 400 | D49: 24 | E49: 9.6 | F49: XY | G49: 112.5
A50: 178509 | B50: BEBELAC 4 HNY GREAT+ 10X1000G FB PGS | C50: 1000 | D50: 10 | E50: 10 | F50: XY | G50: 166.66667
A51: 178499 | B51: BEBELAC 4 HNY GREAT+ 6X2X900G MP PGS | C51: 1800 | D51: 6 | E51: 10.8 | F51: XY | G51: NaN
A52: 178511 | B52: BEBELAC 3 VAN GREAT+ 12X620G FB PGS | C52: 620 | D52: 12 | E52: 7.44 | F52: XY | G52: 145.83333
A53: 178512 | B53: BEBELAC 3 HNY GREAT+ 12X620G FB PGS | C53: 620 | D53: 12 | E53: 7.44 | F53: XY | G53: 145.83333
A54: 195069 | B54: BEBELAC 3 VAN GREAT+ 24X400G FB PGS ZBD | C54: 400 | D54: 24 | E54: 9.6 | F54: XY | G54: 112.5
A55: 195068 | B55: BEBELAC 3 VAN GREAT+ 12X620G FB PGS ZBD | C55: 620 | D55: 12 | E55: 7.44 | F55: XY | G55: 175
A56: 195067 | B56: BEBELAC 3 VAN GREAT+ 10X1000G FB PGS ZBD | C56: 1000 | D56: 10 | E56: 10 | F56: XY | G56: 175
A57: 195075 | B57: BEBELAC 3 HNY GREAT+ 24X200G FB PGS ZBD | C57: 200 | D57: 24 | E57: 4.8 | F57: XY | G57: 112.5
A58: 195074 | B58: BEBELAC 3 HNY GREAT+ 24X400G FB PGS ZBD | C58: 400 | D58: 24 | E58: 9.6 | F58: XY | G58: 112.5
A59: 195073 | B59: BEBELAC 3 HNY GREAT+ 12X620G FB PGS ZBD | C59: 620 | D59: 12 | E59: 7.44 | F59: XY | G59: 175
A60: 195072 | B60: BEBELAC 3 HNY GREAT+ 10X1000G FB PGS ZBD | C60: 1000 | D60: 10 | E60: 10 | F60: XY | G60: 175
A61: 195058 | B61: BEBELAC 4 VAN GREAT+ 24X400G FB PGS ZBD | C61: 400 | D61: 24 | E61: 9.6 | F61: XY | G61: 112.5
A62: 195057 | B62: BEBELAC 4 VAN GREAT+ 10X1000G FB PGS ZBD | C62: 1000 | D62: 10 | E62: 10 | F62: XY | G62: 175
A63: 195059 | B63: BEBELAC 4 HNY GREAT+ 24X400G FB PGS ZBD | C63: 400 | D63: 24 | E63: 9.6 | F63: XY | G63: 112.5
... A389: 171705 | B389: C&G NEXT STEP 4 24X400G FB (PK) | C389: 400 | D389: 24 | E389: 9.6 | F389: CD | G389: 83
A390: 178479 | B390: BEBELAC 3 VAN GREAT+ 24X400G FB PGS | C390: 400 | D390: 24 | E390: 9.6 | F390: CD | G390: NaN
A391: 178506 | B391: BEBELAC 3 VAN GREAT+ 10X1000G FB PGS | C391: 1000 | D391: 10 | E391: 10 | F391: CD | G391: 158.33333
...
